Workbook
Name ACCOUNTS: #REF!
Name NAVISION: #REF!
Name REFS: #REF!

Sheet CC
A1: Date | B1: Description | C1: Amount | D1: Extended Details | E1: Appears On Your Statement As | F1: Address | G1: City/State | H1: Zip Code | I1: Country | J1: Reference | K1: Category | L1: CC Name | M1: G/L Account No
A2: 45668 | B2: ONLINE PAYMENT - THANK YOU | C2: -12021.51 | D2: ONLINE PAYMENT - THANK YOU | E2: ONLINE PAYMENT - THANK YOU | J2: '320250110186972138' | L2: DELTARESERVE | M2: =VLOOKUP(SUBSTITUTE(J2,"'",""),Sheet1!L:M,2,FALSE) -> #N/A
A3: 45668 | B3: ADOBE SYSTEMS Adobe SAN JOSE CA | C3: 21.64 | D3: 567960456 www.adobe.com ADOBE SYSTEMS Adobe Systems SAN JOSE CA Description : 0 Price : 0.1999 www.adobe.com | E3: ADOBE SYSTEMS Adobe SAN JOSE CA | F3: 801 N 34TH ST | G3: SEATTLE WA | H3: 98103 | I3: UNITED STATES | J3: '320250120216930217' | K3: Merchandise & Supplies-Mail Order | L3: AMEXPLATINUM | M3: =VLOOKUP(SUBSTITUTE(J3,"'",""),Sheet1!L:M,2,FALSE) -> 64100
A4: 45668 | B4: GOOGLE *ISHARINGSOFT G.CO/HELPPAY# CA | C4: 16.04 | D4: A0YWKMVS DIGITAL GOODS: APPS GOOGLE *ISHARINGSOFT G.CO/HELPPAY# CA DIGITAL GOODS: APPS | E4: GOOGLE *ISHARINGSOFT G.CO/HELPPAY# CA | F4: 1600 AMPHITHEATRE PKWY | G4: MOUNTAIN VIEW CA | H4: 94043-1351 | I4: UNITED STATES | J4: 320250120218752716' | K4: Business Services-Internet Services | L4: DELTARESERVE | M4: =VLOOKUP(SUBSTITUTE(J4,"'",""),Sheet1!L:M,2,FALSE) -> 64100
A5: 45669 | B5: UBER | C5: 28.32 | D5: FG9QDJ8X LM5CYPCR 10013 Uber Trip help.uber.com CA LM5CYPCR 10013 | E5: Uber Trip help.uber.com CA | F5: 1455 MARKET ST 4TH FLOOR | G5: SAN FRANCISCO CA | H5: 94103 | I5: UNITED STATES | J5: '320250120213109403' | K5: Transportation-Taxis & Coach | L5: DELTARESERVE | M5: =VLOOKUP(SUBSTITUTE(J5,"'",""),Sheet1!L:M,2,FALSE) -> 61130
A6: 45669 | B6: FACEBK *META VERIFIEFB.ME/CC CA | C6: 11.99 | D6: 92545376346 DGTL CONTENT FACEBK *META VERIFIED FB.ME/CC CA DGTL CONTENT | E6: FACEBK *META VERIFIEFB.ME/CC CA | F6: 1 HACKER WAY | G6: MENLO PARK CA | H6: 94025 | I6: UNITED STATES | J6: '320250120231674656' | K6: Business Services-Office Supplies | L6: AMEXPLATINUM | M6: =VLOOKUP(SUBSTITUTE(J6,"'",""),Sheet1!L:M,2,FALSE) -> 54820
A7: 45669 | B7: WEGMANS ASTOR PLACE NEW YORK NY | C7: 63.09 | D7: W15608601385854293656 WEGMANS ASTOR PLACE 156 000000156 NEW YORK NY 5854293656 | E7: WEGMANS ASTOR PLACE NEW YORK NY | F7: 770 BROADWAY | G7: NEW YORK NY | H7: 10003 | I7: UNITED STATES | J7: '320250130246487755' | K7: Merchandise & Supplies-Groceries | L7: AMEXPLATINUM | M7: =VLOOKUP(SUBSTITUTE(J7,"'",""),Sheet1!L:M,2,FALSE) -> 54820
A8: 45670 | B8: ONLINE PAYMENT - THANK YOU | C8: -3000 | D8: ONLINE PAYMENT - THANK YOU | E8: ONLINE PAYMENT - THANK YOU | J8: '320250130233557937' | L8: AMEXPLATINUM | M8: =VLOOKUP(SUBSTITUTE(J8,"'",""),Sheet1!L:M,2,FALSE) -> #N/A
A9: 45670 | B9: LINKEDIN SN P3704854MOUNTAIN VIEW | C9: 40.58 | D9: P370485424 SUBSCRIPTIONS LINKEDIN SN P370485424 MOUNTAIN VIEW SUBSCRIPTIONS | E9: LINKEDIN SN P3704854MOUNTAIN VIEW | F9: 2029 STIERLIN CT STE 200 | G9: MOUNTAIN VIEW CA | H9: 94043-4655 | I9: UNITED STATES | J9: '320250130237878130' | K9: Merchandise & Supplies-Internet Purchase | L9: AMEXPLATINUM | M9: =VLOOKUP(SUBSTITUTE(J9,"'",""),Sheet1!L:M,2,FALSE) -> 61100
A10: 45671 | B10: IN *HEIDI KLING, PHDNEW YORK NY | C10: 300 | D10: 014IAAGAST48289 100033 IN *HEIDI KLING, PHD NEW YORK NY 8289 100033 | E10: IN *HEIDI KLING, PHDNEW YORK NY | F10: 18 EAST 16TH ST RM 503 | G10: NEW YORK NY | H10: 10003-3111 | I10: UNITED STATES | J10: '320250140261104869' | K10: Business Services-Health Care Services | L10: AMEXPLATINUM | M10: =VLOOKUP(SUBSTITUTE(J10,"'",""),Sheet1!L:M,2,FALSE) -> 54820
A11: 45671 | B11: PATREON* MEMBERSHIP SAN FRANCISCO CA | C11: 20.18 | D11: I2DMCP00098 SUPPORT@PATREON.COM PATREON* MEMBERSHIP 523885 SAN FRANCISCO CA SUPPORT@PATREON.COM | E11: PATREON* MEMBERSHIP SAN FRANCISCO CA | F11: 600 TOWNSEND 5TH FLOOR | G11: SAN FRANCISCO CA | H11: 94103 | I11: UNITED STATES | J11: '320250140261791654' | K11: Business Services-Office Supplies | L11: AMEXPLATINUM | M11: =VLOOKUP(SUBSTITUTE(J11,"'",""),Sheet1!L:M,2,FALSE) -> 54820
A12: 45671 | B12: LEMONADE INSURANCE 5INTERNET NY | C12: 50.67 | D12: O8LQZO01079 HELP@LEMONADE.COM LEMONADE INSURANCE 529657 INTERNET NY HELP@LEMONADE.COM | E12: LEMONADE INSURANCE 5INTERNET NY | F12: 5 CROSBY ST FL 3 | G12: NEW YORK NY | H12: 10013 | I12: UNITED STATES | J12: '320250140262399923' | K12: Business Services-Insurance Services | L12: AMEXPLATINUM | M12: =VLOOKUP(SUBSTITUTE(J12,"'",""),Sheet1!L:M,2,FALSE) -> 54820
A13: 45671 | B13: FACTOR75 BATAVIA IL | C13: 65.36 | D13: MR029139295 18885735727 FACTOR75 BATAVIA IL 18885735727 | E13: FACTOR75 BATAVIA IL | F13: 1853 SUNCAST LN | G13: BATAVIA IL | H13: 60510 | I13: UNITED STATES | J13: '320250140265806913' | K13: Merchandise & Supplies-Groceries | L13: AMEXPLATINUM | M13: =VLOOKUP(SUBSTITUTE(J13,"'",""),Sheet1!L:M,2,FALSE) -> 54820
A14: 45671 | B14: FACTOR75 BATAVIA IL | C14: 29.99 | D14: MR029139306 18885735727 FACTOR75 BATAVIA IL 18885735727 | E14: FACTOR75 BATAVIA IL | F14: 1853 SUNCAST LN | G14: BATAVIA IL | H14: 60510 | I14: UNITED STATES | J14: '320250140266087960' | K14: Merchandise & Supplies-Groceries | L14: AMEXPLATINUM | M14: =VLOOKUP(SUBSTITUTE(J14,"'",""),Sheet1!L:M,2,FALSE) -> 54820
A15: 45671 | B15: AT&T | C15: 104.33 | D15: 48255058 800-331-0500 AT&T MOBILITY RECURRING 800-288-2020 TX Description : TELECOMMUNICATIONS Price : 0.00 800-331-0500 | E15: AT&T MOBILITY RECURR800-288-2020 TX | F15: 208 SOUTH AKARD ST FL 10 | G15: DALLAS TX | H15: 75202-4208 | I15: UNITED STATES | J15: '320250150296821107' | K15: Communications-Mobile Telecom | L15: DELTARESERVE | M15: =VLOOKUP(SUBSTITUTE(J15,"'",""),Sheet1!L:M,2,FALSE) -> 65700
A16: 45672 | B16: TST* ELIS NIGHTSHIFTNEW YORK NY | C16: 20.9 | D16: 21105175016 RESTAURANT TST* ELIS NIGHTSHIFT 00055845 NEW YORK NY RESTAURANT | E16: TST* ELIS NIGHTSHIFTNEW YORK NY | F16: 1390 THIRD AVE | G16: NEW YORK NY | H16: 10075 | I16: UNITED STATES | J16: '320250160319748672' | K16: Restaurant-Restaurant | L16: AMEXPLATINUM | M16: =VLOOKUP(SUBSTITUTE(J16,"'",""),Sheet1!L:M,2,FALSE) -> 54820
A17: 45672 | B17: TST* ELIS NIGHTSHIFTNEW YORK NY | C17: 20.9 | D17: 21105175016 RESTAURANT TST* ELIS NIGHTSHIFT 00055845 NEW YORK NY RESTAURANT | E17: TST* ELIS NIGHTSHIFTNEW YORK NY | F17: 1390 THIRD AVE | G17: NEW YORK NY | H17: 10075 | I17: UNITED STATES | J17: '320250160319791823' | K17: Restaurant-Restaurant | L17: AMEXPLATINUM | M17: =VLOOKUP(SUBSTITUTE(J17,"'",""),Sheet1!L:M,2,FALSE) -> 54820
A18: 45672 | B18: TABULAR EDITOR APS COPENHAGEN V DK | C18: 10 | D18: NT_RASZWGMX +4553503099 TABULAR EDITOR APS COPENHAGEN V DK +4553503099 | E18: TABULAR EDITOR APS COPENHAGEN V DK | F18: SUNDKAJ 125 NORDHAVN | H18: 2150 | I18: DENMARK | J18: '320250160323251142' | K18: Merchandise & Supplies-Computer Supplies | L18: DELTARESERVE | M18: =VLOOKUP(SUBSTITUTE(J18,"'",""),Sheet1!L:M,2,FALSE) -> 64100
A19: 45673 | B19: SPLICE.COM NEW YORK CITY NY | C19: 27.99 | D19: NT_RB8R0ADK 3235775423 SPLICE.COM NEW YORK CITY NY 3235775423 | E19: SPLICE.COM NEW YORK CITY NY | F19: 817 BROADWAY 4TH FLOOR | G19: NEW YORK NY | H19: 10003 | I19: UNITED STATES | J19: '320250160313491858' | K19: Merchandise & Supplies-Computer Supplies | L19: AMEXPLATINUM | M19: =VLOOKUP(SUBSTITUTE(J19,"'",""),Sheet1!L:M,2,FALSE) -> 54820
A20: 45673 | B20: UBER EATS help.uber.com CA | C20: 91.19 | D20: 9V9NGXPX 5Z7BARTO 94103 UBER EATS help.uber.com CA 5Z7BARTO 94103 | E20: UBER EATS help.uber.com CA | F20: 1455 MARKET ST - | G20: SAN FRANCISCO CA | H20: 94103 | I20: UNITED STATES | J20: '320250160316131282' | K20: Restaurant-Restaurant | L20: DELTARESERVE | M20: =VLOOKUP(SUBSTITUTE(J20,"'",""),Sheet1!L:M,2,FALSE) -> 54820
A21: 45673 | B21: UPWORK SAN FRANCISCO | C21: 378.72 | D21: T771017188 11376536 12866 INVOICE CHARGE UPWORK SAN FRANCISCO INVOICE CHARGE 11376536 12866 | E21: UPWORK SAN FRANCISCO | F21: 475 BRANNAN ST SUITE 430 | G21: SAN FRANCISCO CA | H21: 94107 | I21: UNITED STATES | J21: '320250160329171458' | K21: Other-Miscellaneous | L21: DELTARESERVE | M21: =VLOOKUP(SUBSTITUTE(J21,"'",""),Sheet1!L:M,2,FALSE) -> 64200
A22: 45673 | B22: WEGMANS ASTOR PLACE NEW YORK NY | C22: 49.57 | D22: W15639500475854293656 WEGMANS ASTOR PLACE 156 000000156 NEW YORK NY 5854293656 | E22: WEGMANS ASTOR PLACE NEW YORK NY | F22: 770 BROADWAY | G22: NEW YORK NY | H22: 10003 | I22: UNITED STATES | J22: '320250170349399169' | K22: Merchandise & Supplies-Groceries | L22: AMEXPLATINUM | M22: =VLOOKUP(SUBSTITUTE(J22,"'",""),Sheet1!L:M,2,FALSE) -> 54820
A23: 45673 | B23: KALL8 08487000633357SEATTLE WA | C23: 15.41 | D23: 004317822624317822629 981191 KALL8 084870006333577 SEATTLE WA 4317822629 981191 | E23: KALL8 08487000633357SEATTLE WA | F23: 417 2ND AVE WEST | G23: SEATTLE WA | H23: 98119 | I23: UNITED STATES | J23: '320250180384383438' | K23: Other-Miscellaneous | L23: AMEXPLATINUM | M23: =VLOOKUP(SUBSTITUTE(J23,"'",""),Sheet1!L:M,2,FALSE) -> 65700
A24: 45674 | B24: CVS PHARMACY NEW YORK NY | C24: 16.83 | D24: 10186013 8007467287 CVS PHARMACY NEW YORK NY Description : PHARMACIES Price : 0.1683 8007467287 | E24: CVS PHARMACY NEW YORK NY | F24: 158 BLEECKER ST | G24: NEW YORK NY | H24: 10012 | I24: UNITED STATES | J24: '320250180376610675' | K24: Merchandise & Supplies-Pharmacies | L24: AMEXPLATINUM | M24: =VLOOKUP(SUBSTITUTE(J24,"'",""),Sheet1!L:M,2,FALSE) -> 54820
A25: 45675 | B25: DUOLINGO PLUS 12 MONPITTSBURGH PA | C25: 83.99 | D25: NT_RBUH16VJ +14125676602 DUOLINGO PLUS 12 MONTH PITTSBURGH PA +14125676602 | E25: DUOLINGO PLUS 12 MONPITTSBURGH PA | F25: 5900 PENN AVE | G25: PITTSBURGH PA | H25: 15206 | I25: UNITED STATES | J25: '320250180364632138' | K25: Other-Education | L25: AMEXPLATINUM | M25: =VLOOKUP(SUBSTITUTE(J25,"'",""),Sheet1!L:M,2,FALSE) -> 54820
A26: 45675 | B26: PETCO.COM 6989 0698 SAN DIEGO CA | C26: 61.75 | D26: 14888690559 858-453-7845 PETCO.COM 6989 0698 SAN DIEGO CA Description : PETS/SUPPLIES/ACC Price : 0.00 858-453-7845 | E26: PETCO.COM 6989 0698 SAN DIEGO CA | F26: 10850 VIA FRONTERA | G26: SAN DIEGO CA | H26: 92127 | I26: UNITED STATES | J26: '320250190401162038' | K26: Merchandise & Supplies-Internet Purchase | L26: AMEXPLATINUM | M26: =VLOOKUP(SUBSTITUTE(J26,"'",""),Sheet1!L:M,2,FALSE) -> 54820
A27: 45675 | B27: EXXONMOBIL 9736 HANNACROIX NY | C27: 43.18 | D27: 00203155 518-756-9700 EXXONMOBIL 9736 HANNACROIX NY Description : 001 Price : 0.00 518-756-9700 | E27: EXXONMOBIL 9736 HANNACROIX NY | F27: - | G27: (800) 243-9966 TX | H27: 77389 | I27: UNITED STATES | J27: '320250190405707295' | K27: Transportation-Fuel | L27: DELTARESERVE | M27: =VLOOKUP(SUBSTITUTE(J27,"'",""),Sheet1!L:M,2,FALSE) -> 63100
A28: 45676 | B28: UNIQLO 5TH AVE NEW YORK NY | C28: 124.3 | D28: C91BEB35-44 FAMILY CLOTHING UNIQLO 5TH AVE NEW YORK NY FAMILY CLOTHING | E28: UNIQLO 5TH AVE NEW YORK NY | F28: 666 5TH AVE FRNT 9 | G28: NEW YORK NY | H28: 10103-0029 | I28: UNITED STATES | J28: '320250190391173789' | K28: Merchandise & Supplies-Clothing Stores | L28: AMEXPLATINUM | M28: =VLOOKUP(SUBSTITUTE(J28,"'",""),Sheet1!L:M,2,FALSE) -> 54820
A29: 45676 | B29: BANANAREPUBLIC US 63NEW YORK NY | C29: 608.6 | D29: 805254 0000000000000000010003 BANANAREPUBLIC US 63 NEW YORK NY 0000000000000000010003 | E29: BANANAREPUBLIC US 63NEW YORK NY | F29: 105 5TH AVE | G29: NEW YORK NY | H29: 10003 | I29: UNITED STATES | J29: '320250200427753786' | K29: Merchandise & Supplies-Clothing Stores | L29: AMEXPLATINUM | M29: =VLOOKUP(SUBSTITUTE(J29,"'",""),Sheet1!L:M,2,FALSE) -> 54820
A30: 45676 | B30: SKYPE LUXEMBOURG | C30: 29.94 | D30: 80640000067 TELECOM SERVICE SKYPE LUXEMBOURG TELECOM SERVICE | E30: SKYPE LUXEMBOURG | F30: SUBMISSIONS USD | G30: USA 000 | H30: 00000 | I30: UNITED STATES | J30: '320250210446082211' | K30: Communications-Telephone Comm | L30: DELTARESERVE | M30: =VLOOKUP(SUBSTITUTE(J30,"'",""),Sheet1!L:M,2,FALSE) -> 64100
A31: 45677 | B31: THE CLEANERS IO, LLCNew York NY | C31: 46.9 | D31: BcgpcW8E9jl squareup.com/receipts THE CLEANERS IO, LLC New York NY squareup.com/receipts | E31: THE CLEANERS IO, LLCNew York NY | F31: 215 THOMPSON ST | G31: NEW YORK NY | H31: 10012 | I31: UNITED STATES | J31: '320250200417808285' | K31: Business Services-Other Services | L31: AMEXPLATINUM | M31: =VLOOKUP(SUBSTITUTE(J31,"'",""),Sheet1!L:M,2,FALSE) -> 67500
A32: 45677 | B32: SPLICE.COM NEW YORK CITY NY | C32: 8.55 | D32: NT_RCBM9V3Z 3235775423 SPLICE.COM NEW YORK CITY NY 3235775423 | E32: SPLICE.COM NEW YORK CITY NY | F32: 817 BROADWAY FLOOR 4 | G32: NEW YORK NY | H32: 10003 | I32: UNITED STATES | J32: '320250200420302666' | K32: Merchandise & Supplies-Computer Supplies | L32: AMEXPLATINUM | M32: =VLOOKUP(SUBSTITUTE(J32,"'",""),Sheet1!L:M,2,FALSE) -> 54820
A33: 45677 | B33: UBER | C33: 41.72 | D33: HNKFEPZ5 WPCCSLXW 10012 Uber Trip help.uber.com CA WPCCSLXW 10012 | E33: Uber Trip help.uber.com CA | F33: 1455 MARKET ST 4TH FLOOR | G33: SAN FRANCISCO CA | H33: 94103 | I33: UNITED STATES | J33: '320250200421677863' | K33: Transportation-Taxis & Coach | L33: DELTARESERVE | M33: =VLOOKUP(SUBSTITUTE(J33,"'",""),Sheet1!L:M,2,FALSE) -> 61130
A34: 45677 | B34: UBER | C34: 35.67 | D34: JGV2DHJ2 TLT27AVX 10022 Uber Trip help.uber.com CA TLT27AVX 10022 | E34: Uber Trip help.uber.com CA | F34: 1455 MARKET ST 4TH FLOOR | G34: SAN FRANCISCO CA | H34: 94103 | I34: UNITED STATES | J34: '320250200421938841' | K34: Transportation-Taxis & Coach | L34: DELTARESERVE | M34: =VLOOKUP(SUBSTITUTE(J34,"'",""),Sheet1!L:M,2,FALSE) -> 61130
A35: 45677 | B35: NYS THRUWAY AUTO REPSTATEN ISLAND NY | C35: 30 | D35: 1P-83240939 TOLL & BRIDGE FEE NYS THRUWAY AUTO REPLEN STATEN ISLAND NY Description : FOR BILLING QUESTIO Price : 0.00 Description : ACCT: 1P-832409396 Price : 0.00 TOLL & BRIDGE FEE | E35: NYS THRUWAY AUTO REPSTATEN ISLAND NY | F35: 1 EDGEWATER ST STE 308 | G35: STATEN ISLAND NY | H35: 10305-4900 | I35: UNITED STATES | J35: '320250200422515828' | K35: Transportation-Tolls & Fees | L35: AMEXPLATINUM | M35: =VLOOKUP(SUBSTITUTE(J35,"'",""),Sheet1!L:M,2,FALSE) -> 61131
A36: 45677 | B36: FACTOR75 BATAVIA IL | C36: -29.99 | D36: MR029139306 18885735727 FACTOR75 BATAVIA IL 18885735727 | E36: FACTOR75 BATAVIA IL | F36: 1853 SUNCAST LN | G36: BATAVIA IL | H36: 60510 | I36: UNITED STATES | J36: '320250210445601194' | K36: Merchandise & Supplies-Groceries | L36: AMEXPLATINUM | M36: =VLOOKUP(SUBSTITUTE(J36,"'",""),Sheet1!L:M,2,FALSE) -> 54820
A37: 45677 | B37: FACTOR75 BATAVIA IL | C37: -65.36 | D37: MR029139295 18885735727 FACTOR75 BATAVIA IL 18885735727 | E37: FACTOR75 BATAVIA IL | F37: 1853 SUNCAST LN | G37: BATAVIA IL | H37: 60510 | I37: UNITED STATES | J37: '320250210445619784' | K37: Merchandise & Supplies-Groceries | L37: AMEXPLATINUM | M37: =VLOOKUP(SUBSTITUTE(J37,"'",""),Sheet1!L:M,2,FALSE) -> 54820
A38: 45677 | B38: MS* MAKEMESURPRISE WALNUT CA | C38: 37.83 | D38: NT_RCNPN8QZ 8332226883 MS* MAKEMESURPRISE WALNUT CA 8332226883 | E38: MS* MAKEMESURPRISE WALNUT CA | F38: 340 SOUTH LEMON AVE 3159 | G38: WALNUT CA | H38: 91789 | I38: UNITED STATES | J38: '320250210451773828' | K38: Merchandise & Supplies-Clothing Stores | L38: AMEXPLATINUM | M38: =VLOOKUP(SUBSTITUTE(J38,"'",""),Sheet1!L:M,2,FALSE) -> 54820
A39: 45677 | B39: EXXONMOBIL 9736 MALDEN ON HUD NY | C39: 38.94 | D39: 00704358 845-246-3510 EXXONMOBIL 9736 MALDEN ON HUD NY Description : 001 Price : 0.00 845-246-3510 | E39: EXXONMOBIL 9736 MALDEN ON HUD NY | F39: - | G39: (800) 243-9966 TX | H39: 77389 | I39: UNITED STATES | J39: '320250210453229075' | K39: Transportation-Fuel | L39: DELTARESERVE | M39: =VLOOKUP(SUBSTITUTE(J39,"'",""),Sheet1!L:M,2,FALSE) -> 63100
A40: 45678 | B40: ONLINE PAYMENT - THANK YOU | C40: -3000 | D40: ONLINE PAYMENT - THANK YOU | E40: ONLINE PAYMENT - THANK YOU | J40: '320250210436627702' | L40: AMEXPLATINUM | M40: =VLOOKUP(SUBSTITUTE(J40,"'",""),Sheet1!L:M,2,FALSE) -> #N/A
...

Sheet Sheet1
A1: Posting Date | B1: Document Type | C1: Document No. | D1: G/L Account No. | E1: Description | F1: Amount | G1: Bal. Account Type | H1: Bal. Account No. | I1: Transaction No. | J1: Entry No. | K1: Reference Text | L1: Ref Clean | M1: G/L Account No.
A2: 45658 | B2: Invoice | C2: G26192 | D2: 61131 | E2: PARKFAST PAYMENT NEWARK NJ | F2: 850 | G2: Vendor | H2: MISC | I2: 22970 | J2: 47051 | K2: '320250010944540760' | L2: =SUBSTITUTE(K2,"'","") -> 320250010944540760 | M2: 61131
A3: 45658 | B3: Invoice | C3: G26193 | D3: 65700 | E3: VERIZON WRLS RCCRNG PMTS | F3: 229.15 | G3: Vendor | H3: MISC | I3: 22950 | J3: 47011 | K3: '320250010950448554' | L3: =SUBSTITUTE(K3,"'","") -> 320250010950448554 | M3: 65700
A4: 45658 | B4: Invoice | C4: G27269 | D4: 64100 | E4: Amazon Web Services AWS.Amazon.com WA | F4: 776.64 | G4: Vendor | H4: MISC | I4: 23851 | J4: 48813 | K4: '320250020977867060' | L4: =SUBSTITUTE(K4,"'","") -> 320250020977867060 | M4: 64100
A5: 45660 | B5: Invoice | C5: G27275 | D5: 65505 | E5: STATE FARM INSURANCEBLOOMINGTON IL | F5: 105.93 | G5: Vendor | H5: MISC | I5: 24105 | J5: 49321 | K5: '320250030988788564' | L5: =SUBSTITUTE(K5,"'","") -> 320250030988788564 | M5: 65505
A6: 45660 | B6: Invoice | C6: G26195 | D6: 61130 | E6: UBER | F6: 22.51 | G6: Vendor | H6: MISC | I6: 22854 | J6: 46819 | K6: '320250030993924733' | L6: =SUBSTITUTE(K6,"'","") -> 320250030993924733 | M6: 61130
A7: 45660 | B7: Invoice | C7: G26194 | D7: 61130 | E7: UBER | F7: 19.94 | G7: Vendor | H7: MISC | I7: 22853 | J7: 46817 | K7: '320250030993947348' | L7: =SUBSTITUTE(K7,"'","") -> 320250030993947348 | M7: 61130
A8: 45660 | B8: Invoice | C8: G26196 | D8: 61130 | E8: UBER | F8: 42.82 | G8: Vendor | H8: MISC | I8: 22855 | J8: 46821 | K8: '320250030994652143' | L8: =SUBSTITUTE(K8,"'","") -> 320250030994652143 | M8: 61130
A9: 45660 | B9: Invoice | C9: G27270 | D9: 67500 | E9: CREDITSECURE CostaMesa CA | F9: 21.39 | G9: Vendor | H9: MISC | I9: 23932 | J9: 48975 | K9: '320250040025658875' | L9: =SUBSTITUTE(K9,"'","") -> 320250040025658875 | M9: 67500
A10: 45660 | B10: Invoice | C10: G27271 | D10: 54820 | E10: HOUSTONST2573 2573 HOUSTON TX | F10: 9.73 | G10: Vendor | H10: MISC | I10: 24444 | J10: 49999 | K10: '320250040028119422' | L10: =SUBSTITUTE(K10,"'","") -> 320250040028119422 | M10: 54820
A11: 45660 | B11: Invoice | C11: G27272 | D11: 54820 | E11: IAH 1362U KPRC CHAN Houston TX | F11: 8.48 | G11: Vendor | H11: MISC | I11: 24445 | J11: 50001 | K11: '320250040032810577' | L11: =SUBSTITUTE(K11,"'","") -> 320250040032810577 | M11: 54820
A12: 45660 | B12: Invoice | C12: G27273 | D12: 64100 | E12: MSFT * E0500UVFU3 00MSBILL.INFO WA | F12: 21.4 | G12: Vendor | H12: MISC | I12: 23836 | J12: 48783 | K12: '320250040035107873' | L12: =SUBSTITUTE(K12,"'","") -> 320250040035107873 | M12: 64100
A13: 45660 | B13: Invoice | C13: G27274 | D13: 54820 | E13: NYX=VENDINGCUSTOMERSCHULA VISTA CA | F13: 5.5 | G13: Vendor | H13: MISC | I13: 24446 | J13: 50003 | K13: '320250040036686356' | L13: =SUBSTITUTE(K13,"'","") -> 320250040036686356 | M13: 54820
... A1792: 45955 | B1792: Invoice | C1792: G29134 | D1792: 61130 | E1792: UBER | F1792: 53.01 | G1792: Vendor | H1792: MISC | I1792: 26906 | J1792: 54934 | K1792: '320252980032626229' | L1792: =SUBSTITUTE(K1792,"'","") -> 320252980032626229 | M1792: 61130

Sheet Sheet5
A3: Row Labels | B3: Sum of Amount
A4: 54820 | B4: 85478.61 | D4: 54820 | E4: 85650.61 | F4: =D4<>G4 -> FALSE | G4: 54820 | H4: 85478.61 | I4: =H4<>E4 -> TRUE
A5: 61100 | B5: 16569.53 | D5: 61100 | E5: 16569.53 | F5: =D5<>G5 -> FALSE | G5: 61100 | H5: 16569.53 | I5: =H5<>E5 -> FALSE
A6: 61110 | B6: 19083.2 | D6: 61110 | E6: 19083.2 | F6: =D6<>G6 -> FALSE | G6: 61110 | H6: 19083.2 | I6: =H6<>E6 -> FALSE
A7: 61120 | B7: 13385.71 | D7: 61120 | E7: 13385.71 | F7: =D7<>G7 -> FALSE | G7: 61120 | H7: 13385.71 | I7: =H7<>E7 -> FALSE
A8: 61130 | B8: 11884.24 | D8: 61130 | E8: 11884.24 | F8: =D8<>G8 -> FALSE | G8: 61130 | H8: 11884.24 | I8: =H8<>E8 -> FALSE
A9: 61131 | B9: 14661.71 | D9: 61131 | E9: 14661.71 | F9: =D9<>G9 -> FALSE | G9: 61131 | H9: 14661.71 | I9: =H9<>E9 -> FALSE
A10: 61133 | B10: 43.5 | D10: 61133 | E10: 43.5 | F10: =D10<>G10 -> FALSE | G10: 61133 | H10: 43.5 | I10: =H10<>E10 -> FALSE
A11: 61200 | B11: 50.69 | D11: 61200 | E11: 50.69 | F11: =D11<>G11 -> FALSE | G11: 61200 | H11: 50.69 | I11: =H11<>E11 -> FALSE
A12: 61215 | B12: 48702.89 | D12: 61215 | E12: 48702.89 | F12: =D12<>G12 -> FALSE | G12: 61215 | H12: 48702.89 | I12: =H12<>E12 -> FALSE
A13: 63100 | B13: 968.3 | D13: 63100 | E13: 968.3 | F13: =D13<>G13 -> FALSE | G13: 63100 | H13: 968.3 | I13: =H13<>E13 -> FALSE
A14: 64100 | B14: 18285.84 | D14: 64100 | E14: 18285.84 | F14: =D14<>G14 -> FALSE | G14: 64100 | H14: 18285.84 | I14: =H14<>E14 -> FALSE
A15: 64101 | B15: 12825.6 | D15: 64101 | E15: 12825.6 | F15: =D15<>G15 -> FALSE | G15: 64101 | H15: 12825.6 | I15: =H15<>E15 -> FALSE
... A22: 80100 | B22: 6484.82 | D22: 80100 | E22: 6484.82 | F22: =D22<>G22 -> FALSE | G22: 80100 | H22: 6484.82 | I22: =H22<>E22 -> FALSE
A23: #N/A | B23: -259021.51
A24: Grand Total | B24: 20963.24
